<?xml version="1.0" encoding='utf-8'?>
<robot xmlns:xacro="http://www.ros.org/wiki/xacro" name="pisa_softfoot">

<!-- ARGS -->
<xacro:property name="leg_mass" value="0.02"/>

<!-- MODELS -->
<xacro:include filename="$(find softfoot_thing_description)/model/softfoot_thing.urdf.xacro"/>

<!-- WORLD -->
<link name="world">
</link>

<!-- LEG 1 -->
<joint name="world_to_leg_1" type="revolute">
    <origin xyz="0 0.2  0.2" rpy="0 0 0"/>
    <axis xyz="0 1 0"/>
    <limit lower="-0.50" upper="0.50" effort="1" velocity="1" />
    <dynamics friction="0.0001" damping="0.0001"/>
    <parent link="world"/>
    <child link="leg_link_1"/>
</joint>
  
<link name="leg_link_1">
    <inertial>
        <mass value="${leg_mass}"/>
        <origin xyz="0 0 0" rpy="0 0 0"/>
        <inertia    ixx="${mm2tom2 * 1}" iyy="${mm2tom2 * 1}" izz="${mm2tom2 * 1}"
                    ixy="0" ixz="0" iyz="0"/>
        </inertial>
    <visual>
        <origin xyz="0 0 0" rpy="0 0 0"/>
        <geometry>
            <cylinder length="0.1" radius="0.015"/>
        </geometry>
        <material name="SoftFoot/Black"/>
    </visual>
    <collision>
        <origin xyz="0 0 0" rpy="0 0 0"/>
        <geometry>
            <cylinder length="0.1" radius="0.015"/>
        </geometry>
    </collision>
</link>

<gazebo reference="leg_link_1">
    <gravity>true</gravity>
    <material>Gazebo/Black</material>
</gazebo>

<!-- FOOT 1 -->
<xacro:softfoot_thing name="softfoot_1" parent="leg_link_1">
    <origin xyz="0 0 -0.05" rpy="0 0 0"/>
</xacro:softfoot_thing>


  <!-- LEG 2 -->
    <joint name="world_to_leg_2" type="revolute">
        <origin xyz="0 0.0 0.2" rpy="0 0 0"/>
        <axis xyz="0 1 0"/>
        <limit lower="-0.50" upper="0.50" effort="1" velocity="1" />
        <dynamics friction="0.0001" damping="0.0001"/>
        <parent link="world"/>
        <child link="leg_link_2"/>
    </joint>

  <link name="leg_link_2">
    <inertial>
			<mass value="${leg_mass}"/>
			<origin xyz="0 0 0" rpy="0 0 0"/>
			<inertia  ixx="${mm2tom2 * 1}" iyy="${mm2tom2 * 1}" izz="${mm2tom2 * 1}"
                ixy="0" ixz="0" iyz="0"/>
		</inertial>
    <visual>
      <origin xyz="0 0 0" rpy="0 0 0"/>
      <geometry>
        <cylinder length="0.1" radius="0.015"/>
      </geometry>
      <material name="SoftFoot/Black"/>
    </visual>
    <collision>
			<origin xyz="0 0 0" rpy="0 0 0"/>
			<geometry>
        <cylinder length="0.1" radius="0.015"/>
      </geometry>
		</collision>
  </link>

  <gazebo reference="leg_link_2">
		<gravity>true</gravity>
		<material>Gazebo/Black</material>
	</gazebo>

  <!-- FOOT 2 -->
 <xacro:softfoot_thing name="softfoot_2" parent="leg_link_2">
    <origin xyz="0 0 -0.05" rpy="0 0 0"/>
  </xacro:softfoot_thing>


    <!-- LEG 3 -->
    <joint name="world_to_leg_3" type="revolute">
        <origin xyz="-0.2 0.2 0.2" rpy="0 0 0"/>
        <axis xyz="0 1 0"/>
        <limit lower="-0.50" upper="0.50" effort="1" velocity="1" />
        <dynamics friction="0.0001" damping="0.0001"/>
        <parent link="world"/>
        <child link="leg_link_3"/>
    </joint>

    <link name="leg_link_3">
        <inertial>
            <mass value="${leg_mass}"/>
            <origin xyz="0 0 0" rpy="0 0 0"/>
            <inertia  ixx="${mm2tom2 * 1}" iyy="${mm2tom2 * 1}" izz="${mm2tom2 * 1}"
                      ixy="0" ixz="0" iyz="0"/>
        </inertial>
        <visual>
            <origin xyz="0 0 0" rpy="0 0 0"/>
            <geometry>
                <cylinder length="0.1" radius="0.015"/>
            </geometry>
            <material name="SoftFoot/Black"/>
        </visual>
        <collision>
            <origin xyz="0 0 0" rpy="0 0 0"/>
            <geometry>
                <cylinder length="0.1" radius="0.015"/>
            </geometry>
        </collision>
    </link>

    <gazebo reference="leg_link_3">
        <gravity>true</gravity>
        <material>Gazebo/Black</material>
    </gazebo>

    <!-- FOOT 3 -->
    <xacro:softfoot_thing name="softfoot_3" parent="leg_link_3">
        <origin xyz="0 0 -0.05" rpy="0 0 0"/>
    </xacro:softfoot_thing>

    <!-- LEG 4 -->
    <joint name="world_to_leg_4" type="revolute">
        <origin xyz="-0.2 0.0 0.2" rpy="0 0 0"/>
        <axis xyz="0 1 0"/>
        <limit lower="-0.50" upper="0.50" effort="1" velocity="1" />
        <dynamics friction="0.0001" damping="0.0001"/>
        <parent link="world"/>
        <child link="leg_link_4"/>
    </joint>

    <link name="leg_link_4">
        <inertial>
            <mass value="${leg_mass}"/>
            <origin xyz="0 0 0" rpy="0 0 0"/>
            <inertia  ixx="${mm2tom2 * 1}" iyy="${mm2tom2 * 1}" izz="${mm2tom2 * 1}"
                      ixy="0" ixz="0" iyz="0"/>
        </inertial>
        <visual>
            <origin xyz="0 0 0" rpy="0 0 0"/>
            <geometry>
                <cylinder length="0.1" radius="0.015"/>
            </geometry>
            <material name="SoftFoot/Black"/>
        </visual>
        <collision>
            <origin xyz="0 0 0" rpy="0 0 0"/>
            <geometry>
                <cylinder length="0.1" radius="0.015"/>
            </geometry>
        </collision>
    </link>

    <gazebo reference="leg_link_4">
        <gravity>true</gravity>
        <material>Gazebo/Black</material>
    </gazebo>

    <!-- FOOT 3 -->
    <xacro:softfoot_thing name="softfoot_4" parent="leg_link_4">
        <origin xyz="0 0 -0.05" rpy="0 0 0"/>
    </xacro:softfoot_thing>

</robot>
