<?xml version="1.0" encoding='utf-8'?>
<robot xmlns:xacro="http://www.ros.org/wiki/xacro" name="pisa_softfoot">

<!-- ARGS -->
<xacro:property name="leg_mass" value="0.02"/>

<!-- MODELS -->
<xacro:include filename="$(find softfoot_thing_description)/model/softfoot_thing.urdf.xacro"/>

<!-- WORLD -->
<link name="world">
</link>

<!-- LEG -->
<joint name="world_to_leg" type="prismatic">
    <origin xyz="0 0 0.5" rpy="0 0 0"/>
    <axis xyz="0 0 -1"/>
    <limit lower="-0.50" upper="0.50" effort="1" velocity="1" />
    <dynamics friction="0.0" damping="0.0"/>
    <parent link="world"/>
    <child link="leg_link"/>
</joint>

<link name="leg_link">
    <inertial>
        <mass value="${leg_mass}"/>
        <origin xyz="0 0 0" rpy="0 0 0"/>
        <inertia    ixx="${mm2tom2 * 1}" iyy="${mm2tom2 * 1}" izz="${mm2tom2 * 1}"
                    ixy="0" ixz="0" iyz="0"/>
        </inertial>
    <visual>
        <origin xyz="0 0 0" rpy="0 0 0"/>
        <geometry>
            <cylinder length="0.1" radius="0.015"/>
        </geometry>
        <material name="SoftFoot/Black"/>
    </visual>
    <collision>
        <origin xyz="0 0 0" rpy="0 0 0"/>
        <geometry>
            <cylinder length="0.1" radius="0.015"/>
        </geometry>
    </collision>
</link>

<gazebo reference="leg_link">
    <gravity>true</gravity>
    <material>Gazebo/Black</material>
</gazebo>

<!-- FOOT 1 -->
<xacro:softfoot_thing name="softfoot" parent="leg_link">
    <origin xyz="0 0 -0.05" rpy="0 0 0"/>
</xacro:softfoot_thing>

</robot>
